Workbook

Sheet Produtos
A1: id_produto | B1: categoria | C1: produto | D1: variante | E1: unidade_venda | F1: quantidade_minima | G1: limite_sabores | H1: preco | I1: unidade_preco | J1: observacoes
A2: P001 | B2: Mini Cupcakes | C2: Mini Cupcake | D2: Tradicional | E2: unidade | F2: 12 | G2: até 2 sabores | H2: 4 | I2: cada | J2: Sem sainha. Recheio e cobertura à escolha.
A3: P002 | B3: Mini Cupcakes | C3: Mini Cupcake | D3: Especial | E3: unidade | F3: 12 | G3: até 2 sabores | H3: 5 | I3: cada | J3: Com sainhas e tags no tema. Recheio e cobertura à escolha.
A4: P003 | B4: Cupcakes | C4: Cupcake | D4: Tradicional | E4: unidade | F4: 10 | G4: não informado | H4: 8 | I4: cada | J4: Recheio e cobertura à escolha. Embalagem de presente sob consulta.
A5: P004 | B5: Cupcakes | C5: Cupcake | D5: Especial | E5: unidade | F5: 10 | G5: não informado | H5: 9 | I5: cada | J5: Recheio e cobertura à escolha. Embalagem de presente sob consulta.
A6: P005 | B6: Docinhos | C6: Doces Tradicionais | D6: 50 unidades | E6: pacote | F6: 50 | G6: 1 sabor | H6: 110 | I6: pacote | J6: 20g; decoração com granulados comuns; confeito simples sem taxa adicional.
A7: P006 | B7: Docinhos | C7: Doces Tradicionais | D7: 100 unidades | E7: pacote | F7: 100 | G7: até 2 sabores | H7: 200 | I7: pacote | J7: 20g; decoração com granulados comuns; confeito simples sem taxa adicional.
A8: P007 | B8: Docinhos | C8: Doces Gourmets | D8: 50 unidades | E8: pacote | F8: 50 | G8: 1 sabor | H8: 130 | I8: pacote | J8: 20g; granulados especiais.
A9: P008 | B9: Docinhos | C9: Doces Gourmets | D9: 100 unidades | E9: pacote | F9: 100 | G9: até 2 sabores | H9: 250 | I9: pacote | J9: 20g; granulados especiais.
A10: P009 | B10: Docinhos | C10: Doces Especiais | D10: 50 unidades | E10: pacote | F10: 50 | G10: 1 sabor | H10: 140 | I10: pacote | J10: 20g; sabores especiais.
A11: P010 | B11: Docinhos | C11: Doces Especiais | D11: 100 unidades | E11: pacote | F11: 100 | G11: até 2 sabores | H11: 270 | I11: pacote | J11: 20g; sabores especiais.
A12: P011 | B12: Casquinhas de chocolate | C12: Casquinha | D12: Grupo 1 / 50 unidades | E12: pacote | F12: 50 | G12: não informado | H12: 115 | I12: pacote | J12: Categoria agrupada a partir do portfólio; confirmar nomenclatura exata com a dona do ateliê.
A13: P012 | B13: Casquinhas de chocolate | C13: Casquinha | D13: Grupo 1 / 100 unidades | E13: pacote | F13: 100 | G13: não informado | H13: 220 | I13: pacote | J13: Categoria agrupada a partir do portfólio; confirmar nomenclatura exata com a dona do ateliê.
... A34: P033 | B34: Decoração | C34: Naked Cake | D34: Adicional | E34: kg | F34: 1 | G34: não se aplica | H34: 10 | I34: kg | J34: Adicional de modelo/decoração.

Sheet Sabores_Opcoes
A1: id_opcao | B1: categoria | C1: produto_base | D1: tipo_opcao | E1: opcao | F1: grupo_preco | G1: observacoes | H1: pagina_fonte
A2: S001 | B2: Mini Cupcakes | C2: Mini Cupcake Tradicional | D2: Recheio | E2: Beijinho de coco | H2: p.2
A3: S002 | B3: Mini Cupcakes | C3: Mini Cupcake Tradicional | D3: Recheio | E3: Maracujá | H3: p.2
A4: S003 | B4: Mini Cupcakes | C4: Mini Cupcake Tradicional | D4: Recheio | E4: Brigadeiro ao leite | H4: p.2
A5: S004 | B5: Mini Cupcakes | C5: Mini Cupcake Tradicional | D5: Recheio | E5: Doce de leite | H5: p.2
A6: S005 | B6: Mini Cupcakes | C6: Mini Cupcake Tradicional | D6: Recheio | E6: Limão | H6: p.2
A7: S006 | B7: Mini Cupcakes | C7: Mini Cupcake Tradicional | D7: Cobertura | E7: Creme de moça | H7: p.2
A8: S007 | B8: Mini Cupcakes | C8: Mini Cupcake Tradicional | D8: Cobertura | E8: Brigadeiro | H8: p.2
A9: S008 | B9: Mini Cupcakes | C9: Mini Cupcake Tradicional | D9: Cobertura | E9: Chantininho | H9: p.2
A10: S009 | B10: Mini Cupcakes | C10: Mini Cupcake Especial | D10: Recheio | E10: Maracujá | H10: p.2
A11: S010 | B11: Mini Cupcakes | C11: Mini Cupcake Especial | D11: Recheio | E11: Brigadeiro | H11: p.2
A12: S011 | B12: Mini Cupcakes | C12: Mini Cupcake Especial | D12: Recheio | E12: Leite ninho | H12: p.2
A13: S012 | B13: Mini Cupcakes | C13: Mini Cupcake Especial | D13: Recheio | E13: Nutella | H13: p.2
... A39: S038 | B39: Cupcakes | C39: Cupcake Especial | D39: Cobertura | E39: Chantininho | H39: p.3
A40: S039 | B40: Docinhos | C40: Doces Tradicionais | D40: Sabor | E40: Cajuzinho | F40: Tradicional | H40: p.4
A41: S040 | B41: Docinhos | C41: Doces Tradicionais | D41: Sabor | E41: Leite Ninho | F41: Tradicional | H41: p.4
A42: S041 | B42: Docinhos | C42: Doces Tradicionais | D42: Sabor | E42: Beijinho de coco | F42: Tradicional | H42: p.4
A43: S042 | B43: Docinhos | C43: Doces Tradicionais | D43: Sabor | E43: Brigadeiro ao leite | F43: Tradicional | H43: p.4
A44: S043 | B44: Docinhos | C44: Doces Gourmets | D44: Sabor | E44: Brigadeiro ao leite | F44: Gourmet | H44: p.4
A45: S044 | B45: Docinhos | C45: Doces Gourmets | D45: Sabor | E45: Leite ninho c/ nutella | F45: Gourmet | H45: p.4
A46: S045 | B46: Docinhos | C46: Doces Gourmets | D46: Sabor | E46: Casadinho | F46: Gourmet | H46: p.4
A47: S046 | B47: Docinhos | C47: Doces Especiais | D47: Sabor | E47: Ninho com uva | F47: Especial | H47: p.4
A48: S047 | B48: Docinhos | C48: Doces Especiais | D48: Sabor | E48: Olho de sogra | F48: Especial | H48: p.4
A49: S048 | B49: Docinhos | C49: Doces Especiais | D49: Sabor | E49: Olho de sogro | F49: Especial | H49: p.4
A50: S049 | B50: Casquinhas de chocolate | C50: Casquinha | D50: Recheio | E50: Amendoim | F50: Casquinhas | H50: p.5
A51: S050 | B51: Casquinhas de chocolate | C51: Casquinha | D51: Recheio | E51: Ameixa | F51: Casquinhas | H51: p.5
... A78: S077 | B78: Bombons Trufados | C78: Bombom trufado | D78: Recheio | E78: Ninho com nutella | F78: Bombons | H78: p.6
A79: S078 | B79: Bolos | C79: Bolo | D79: Massa | E79: Branca Tradicional | H79: p.7
A80: S079 | B80: Bolos | C80: Bolo | D80: Massa | E80: Baunilha | H80: p.7
A81: S080 | B81: Bolos | C81: Bolo | D81: Massa | E81: Chocolate | H81: p.7
A82: S081 | B82: Bolos | C82: Bolo Tradicional | D82: Recheio | E82: Brigadeiro ao leite | F82: Tradicional | H82: p.8
A83: S082 | B83: Bolos | C83: Bolo Tradicional | D83: Recheio | E83: Creme de moça | F83: Tradicional | H83: p.8
A84: S083 | B84: Bolos | C84: Bolo Tradicional | D84: Recheio | E84: Doce de leite | F84: Tradicional | H84: p.8
A85: S084 | B85: Bolos | C85: Bolo Tradicional | D85: Recheio | E85: Recheio de Nata | F85: Tradicional | H85: p.8
A86: S085 | B86: Bolos | C86: Bolo Tradicional | D86: Recheio | E86: Ganache de chocolate ao leite ou meio amargo | F86: Tradicional | H86: p.8
A87: S086 | B87: Bolos | C87: Bolo Tradicional | D87: Recheio | E87: Leite ninho | F87: Tradicional | H87: p.8
A88: S087 | B88: Bolos | C88: Bolo Tradicional | D88: Recheio | E88: Abacaxi | F88: Tradicional | H88: p.8
A89: S088 | B89: Bolos | C89: Bolo Tradicional | D89: Recheio | E89: Limão | F89: Tradicional | H89: p.8
A90: S089 | B90: Bolos | C90: Bolo Especial | D90: Recheio | E90: Baba de moça c/ abacaxi | F90: Especial | H90: p.8
A91: S090 | B91: Bolos | C91: Bolo Especial | D91: Recheio | E91: Baba de moça c/ morango | F91: Especial | H91: p.8
...

Sheet Tamanhos_Bolos
A1: id_tamanho | B1: peso_kg | C1: aro_cm | D1: serve_pessoas | E1: fatias_aproximadas | F1: observacoes | G1: pagina_fonte
A2: T001 | B2: 1 | C2: 13 | D2: 8-10 | E2: 10 | F2: Recomendado calcular no mínimo 100g por convidado. | G2: p.7
A3: T002 | B3: 1.5 | C3: 15 | D3: 13-15 | E3: 15 | F3: Recomendado calcular no mínimo 100g por convidado. | G3: p.7
A4: T003 | B4: 2 | C4: 17 | D4: 17-20 | E4: 20 | F4: Recomendado calcular no mínimo 100g por convidado. | G4: p.7
A5: T004 | B5: 2.5 | C5: 20 | D5: 23-25 | E5: 25 | F5: Recomendado calcular no mínimo 100g por convidado. | G5: p.7
A6: T005 | B6: 3 | C6: 23 | D6: 28-30 | E6: 30 | F6: Recomendado calcular no mínimo 100g por convidado. | G6: p.7
A7: T006 | B7: 4 | C7: 25 | D7: 38-40 | E7: 40 | F7: Temos aros maiores. | G7: p.7

Sheet Decoracoes
A1: id_decoracao | B1: tipo | C1: nome | D1: preco | E1: unidade_preco | F1: observacoes | G1: pagina_fonte
A2: D001 | B2: Simples | C2: Babados | D2: 0 | E2: sem acréscimo | F2: Decoração simples em chantininho. | G2: p.9
A3: D002 | B3: Simples | C3: Guirlanda | D3: 0 | E3: sem acréscimo | F3: Decoração simples em chantininho. | G3: p.9
A4: D003 | B4: Simples | C4: Jardim | D4: 0 | E4: sem acréscimo | F4: Decoração simples em chantininho. | G4: p.9
A5: D004 | B5: Simples | C5: Cordinhas | D5: 0 | E5: sem acréscimo | F5: Decoração simples em chantininho. | G5: p.9
A6: D005 | B6: Simples | C6: Textura | D6: 0 | E6: sem acréscimo | F6: Decoração simples em chantininho. | G6: p.9
A7: D006 | B7: Simples | C7: Liso | D7: 0 | E7: sem acréscimo | F7: Decoração simples em chantininho. | G7: p.9
A8: D007 | B8: Simples | C8: Espatulado | D8: 0 | E8: sem acréscimo | F8: Decoração simples em chantininho. | G8: p.9
A9: D008 | B9: Especial | C9: Bolo de andar | E9: consultar | F9: Modelo listado como decoração/modelo especial. | G9: p.9, p.12, p.13
A10: D009 | B10: Especial | C10: Bolo com 20cm de altura | D10: 5 | E10: kg | F10: Adicional por kg. | G10: p.9
A11: D010 | B11: Especial | C11: Naked Cake | D11: 10 | E11: kg | F11: Adicional por kg. | G11: p.9, p.12
A12: D011 | B12: Especial | C12: Unicórnio | E12: consultar | F12: Modelo demonstrativo no portfólio. | G12: p.9, p.11
A13: D012 | B13: Especial | C13: Rococó | E13: consultar | F13: Modelo demonstrativo no portfólio. | G13: p.9, p.12
A14: D013 | B14: Especial | C14: Rosas | E14: consultar | F14: Modelo listado. | G14: p.9
A15: D014 | B15: Especial | C15: Drip | E15: consultar | F15: Modelo demonstrativo no portfólio. | G15: p.9, p.11
A16: D015 | B16: Especial | C16: Cores em degradê | E16: consultar | F16: Modelo demonstrativo no portfólio. | G16: p.9, p.12
A17: D016 | B17: Especial | C17: Colorido de 3 cores | E17: consultar | F17: Modelo listado. | G17: p.9
A18: D017 | B18: Especial | C18: Bolo espatulado no acetato | E18: consultar | F18: Modelo listado. | G18: p.9
A19: D018 | B19: Adicional | C19: Cor forte/metalizado - 1,5kg ou 2kg | D19: 5 | E19: adicional | F19: Adicional por cor forte ou metalizado. | G19: p.9
A20: D019 | B20: Adicional | C20: Cor forte/metalizado - 3kg ou 4kg | D20: 8 | E20: adicional | F20: Adicional por cor forte ou metalizado. | G20: p.9
A21: D020 | B21: Adicional | C21: Cor forte/metalizado - 5kg | D21: 12 | E21: adicional | F21: Adicional por cor forte ou metalizado. | G21: p.9
A22: D021 | B22: Modelo | C22: Bolo com flores | E22: consultar | F22: Modelo demonstrativo. | G22: p.11
A23: D022 | B23: Modelo | C23: Bolo com ondas | E23: consultar | F23: Modelo demonstrativo. | G23: p.11
A24: D023 | B24: Modelo | C24: Com KitKat | E24: consultar | F24: Modelo demonstrativo. | G24: p.12
A25: D024 | B25: Modelo | C25: Bolo alto | E25: consultar | F25: Modelo demonstrativo. | G25: p.12
A26: D025 | B26: Modelo | C26: Semi Naked Cake | E26: consultar | F26: Modelo demonstrativo. | G26: p.13
A27: D026 | B27: Modelo | C27: Bolo baixo | E27: consultar | F27: Modelo demonstrativo. | G27: p.13
A28: D027 | B28: Modelo | C28: Temático | E28: consultar | F28: Modelo demonstrativo. | G28: p.13

Sheet Informacoes
A1: campo | B1: informacao | C1: pagina_fonte
A2: WhatsApp para encomendas | B2: (61) 99501-8735 | C2: p.16
A3: Atendimento | B3: Segunda a sexta de 9h às 20h; sábado de 9h às 12h | C3: p.16
A4: Retirada | B4: Encomendas retiradas em data e horário pré-agendado | C4: p.16
A5: Formas de pagamento | B5: Pix, transferência bancária, cartão ou dinheiro | C5: p.16
A6: Entrada para agendamento | B6: Agenda de produção somente após pagamento de 50% do valor definido | C6: p.16
A7: Política de desistência | B7: Reembolso integral até 5 dias antes da data e horário agendados para retirada; após o prazo, o valor pago não será devolvido | C7: p.16
A8: Endereço de retirada | B8: Acampamento DFL, Rua do Campo casa 5E, Vila Planalto | C8: p.16
A9: Instagram | B9: @bolo_dapreta | C9: p.10, p.16
A10: E-mail | B10: lucineide.preta.lc@gmail.com | C10: p.16
A11: Última atualização do menu | B11: 19/09/2022 | C11: p.9

Sheet Clientes
A1: id_cliente | B1: nome | C1: telefone | D1: observacoes
A2: C001 | B2: Maria Silva | C2: (61) 99999-9999 | D2: Retira no local
A3: C002 | B3: Ana Paula | C3: (61) 98888-8888 | D3: Paga cartão

Sheet Pedidos
A1: id_pedido | B1: id_cliente | C1: data_pedido | D1: data_entrega | E1: horario_entrega | F1: status | G1: forma_pagamento | H1: valor_total | I1: sinal_50 | J1: observacoes
A2: PED001 | B2: C001 | C2: 46149 | D2: 46152 | E2: 15:00 | F2: pendente | G2: pix | H2: =SUMIF(Itens_Pedido!B:B,A2,Itens_Pedido!H:H) -> 48 | I2: =H2*0.5 -> 24 | J2: Pedido exemplo; apagar depois
A3: PED002 | B3: C001 | C3: 46149 | D3: 46154 | E3: 0.5 | F3: pendente | G3: pix | H3: =SUMIF(Itens_Pedido!B:B,A3,Itens_Pedido!H:H) -> 0 | I3: =H3*0.5 -> 0
H4: =SUMIF(Itens_Pedido!B:B,A4,Itens_Pedido!H:H) -> 0 | I4: =H4*0.5 -> 0
H5: =SUMIF(Itens_Pedido!B:B,A5,Itens_Pedido!H:H) -> 0 | I5: =H5*0.5 -> 0
H6: =SUMIF(Itens_Pedido!B:B,A6,Itens_Pedido!H:H) -> 0 | I6: =H6*0.5 -> 0
H7: =SUMIF(Itens_Pedido!B:B,A7,Itens_Pedido!H:H) -> 0 | I7: =H7*0.5 -> 0
H8: =SUMIF(Itens_Pedido!B:B,A8,Itens_Pedido!H:H) -> 0 | I8: =H8*0.5 -> 0
H9: =SUMIF(Itens_Pedido!B:B,A9,Itens_Pedido!H:H) -> 0 | I9: =H9*0.5 -> 0
H10: =SUMIF(Itens_Pedido!B:B,A10,Itens_Pedido!H:H) -> 0 | I10: =H10*0.5 -> 0
H11: =SUMIF(Itens_Pedido!B:B,A11,Itens_Pedido!H:H) -> 0 | I11: =H11*0.5 -> 0
H12: =SUMIF(Itens_Pedido!B:B,A12,Itens_Pedido!H:H) -> 0 | I12: =H12*0.5 -> 0
H13: =SUMIF(Itens_Pedido!B:B,A13,Itens_Pedido!H:H) -> 0 | I13: =H13*0.5 -> 0
H14: =SUMIF(Itens_Pedido!B:B,A14,Itens_Pedido!H:H) -> 0 | I14: =H14*0.5 -> 0
H15: =SUMIF(Itens_Pedido!B:B,A15,Itens_Pedido!H:H) -> 0 | I15: =H15*0.5 -> 0
... H100: =SUMIF(Itens_Pedido!B:B,A100,Itens_Pedido!H:H) -> 0 | I100: =H100*0.5 -> 0

Sheet Itens_Pedido
A1: id_item | B1: id_pedido | C1: id_produto | D1: produto | E1: quantidade | F1: unidade | G1: preco_unitario | H1: subtotal | I1: observacoes
A2: I001 | B2: PED001 | C2: P001 | D2: Mini Cupcake Tradicional | E2: 12 | F2: unidade | G2: 4 | H2: =E2*G2 -> 48 | I2: Item exemplo; apagar depois
A3: I002 | B3: PED001 | C3: P014 | D3: Casquinhas de Chocolate | E3: 100 | F3: pacote
